mythril.mythril.mythril_analyzer [CRITICAL]: Exception occurred, aborting analysis. Please report this issue to the Mythril GitHub page.
Traceback (most recent call last):
  File "/home/ubuntu/.local/lib/python3.6/site-packages/mythril/mythril/mythril_analyzer.py", line 162, in fire_lasers
    custom_modules_directory=self.custom_modules_directory,
  File "/home/ubuntu/.local/lib/python3.6/site-packages/mythril/analysis/symbolic.py", line 166, in __init__
    world_state=world_state,
  File "/home/ubuntu/.local/lib/python3.6/site-packages/mythril/laser/ethereum/svm.py", line 175, in sym_exec
    self._execute_transactions(created_account.address)
  File "/home/ubuntu/.local/lib/python3.6/site-packages/mythril/laser/ethereum/svm.py", line 216, in _execute_transactions
    execute_message_call(self, address)
  File "/home/ubuntu/.local/lib/python3.6/site-packages/mythril/laser/ethereum/transaction/symbolic.py", line 108, in execute_message_call
    laser_evm.exec()
  File "/home/ubuntu/.local/lib/python3.6/site-packages/mythril/laser/ethereum/svm.py", line 260, in exec
    for state in new_states
  File "/home/ubuntu/.local/lib/python3.6/site-packages/mythril/laser/ethereum/svm.py", line 261, in <listcomp>
    if state.world_state.constraints.is_possible
  File "/home/ubuntu/.local/lib/python3.6/site-packages/mythril/laser/ethereum/state/constraints.py", line 32, in is_possible
    get_model(tuple(self[:]))
  File "/home/ubuntu/.local/lib/python3.6/site-packages/mythril/support/model.py", line 57, in get_model
    result = s.check()
  File "/home/ubuntu/.local/lib/python3.6/site-packages/mythril/laser/smt/solver/solver_statistics.py", line 19, in function_wrapper
    result = func(*args, **kwargs)
  File "/home/ubuntu/.local/lib/python3.6/site-packages/mythril/laser/smt/solver/solver.py", line 55, in check
    evaluate = self.raw.check(args)
  File "/home/ubuntu/.local/lib/python3.6/site-packages/z3/z3.py", line 7534, in check
    return CheckSatResult(Z3_optimize_check(self.ctx.ref(), self.optimize, num, _assumptions))
  File "/home/ubuntu/.local/lib/python3.6/site-packages/z3/z3core.py", line 4468, in Z3_optimize_check
    _elems.Check(a0)
  File "/home/ubuntu/.local/lib/python3.6/site-packages/z3/z3core.py", line 1420, in Check
    raise self.Exception(self.get_error_message(ctx, err))
z3.z3types.Z3Exception: b'push canceled'


---------------------------------------------
For contract 0x188C2274B04Ea392B21487b5De299e382Ff84246.sol
Tool Runtime = 6599.144182446999 seconds
#############################################