mythril.mythril.mythril_analyzer [CRITICAL]: Exception occurred, aborting analysis. Please report this issue to the Mythril GitHub page.
Traceback (most recent call last):
  File "/home/ubuntu/.local/lib/python3.6/site-packages/mythril/mythril/mythril_analyzer.py", line 162, in fire_lasers
    custom_modules_directory=self.custom_modules_directory,
  File "/home/ubuntu/.local/lib/python3.6/site-packages/mythril/analysis/symbolic.py", line 166, in __init__
    world_state=world_state,
  File "/home/ubuntu/.local/lib/python3.6/site-packages/mythril/laser/ethereum/svm.py", line 175, in sym_exec
    self._execute_transactions(created_account.address)
  File "/home/ubuntu/.local/lib/python3.6/site-packages/mythril/laser/ethereum/svm.py", line 216, in _execute_transactions
    execute_message_call(self, address)
  File "/home/ubuntu/.local/lib/python3.6/site-packages/mythril/laser/ethereum/transaction/symbolic.py", line 108, in execute_message_call
    laser_evm.exec()
  File "/home/ubuntu/.local/lib/python3.6/site-packages/mythril/laser/ethereum/svm.py", line 253, in exec
    new_states, op_code = self.execute_state(global_state)
  File "/home/ubuntu/.local/lib/python3.6/site-packages/mythril/laser/ethereum/svm.py", line 335, in execute_state
    self._execute_pre_hook(op_code, global_state)
  File "/home/ubuntu/.local/lib/python3.6/site-packages/mythril/laser/ethereum/svm.py", line 654, in _execute_pre_hook
    hook(global_state)
  File "/home/ubuntu/.local/lib/python3.6/site-packages/mythril/analysis/module/base.py", line 69, in execute
    result = self._execute(target)
  File "/home/ubuntu/.local/lib/python3.6/site-packages/mythril/analysis/module/modules/integer.py", line 131, in _execute
    func(state)
  File "/home/ubuntu/.local/lib/python3.6/site-packages/mythril/analysis/module/modules/integer.py", line 182, in _handle_exp
    constraint = op0.value ** op1.value >= 2 ** 256
MemoryError

