mythril.mythril.mythril_analyzer [CRITICAL]: Exception occurred, aborting analysis. Please report this issue to the Mythril GitHub page.
Traceback (most recent call last):
  File "/home/ubuntu/.local/lib/python3.6/site-packages/mythril/mythril/mythril_analyzer.py", line 162, in fire_lasers
    custom_modules_directory=self.custom_modules_directory,
  File "/home/ubuntu/.local/lib/python3.6/site-packages/mythril/analysis/symbolic.py", line 166, in __init__
    world_state=world_state,
  File "/home/ubuntu/.local/lib/python3.6/site-packages/mythril/laser/ethereum/svm.py", line 175, in sym_exec
    self._execute_transactions(created_account.address)
  File "/home/ubuntu/.local/lib/python3.6/site-packages/mythril/laser/ethereum/svm.py", line 216, in _execute_transactions
    execute_message_call(self, address)
  File "/home/ubuntu/.local/lib/python3.6/site-packages/mythril/laser/ethereum/transaction/symbolic.py", line 108, in execute_message_call
    laser_evm.exec()
  File "/home/ubuntu/.local/lib/python3.6/site-packages/mythril/laser/ethereum/svm.py", line 260, in exec
    for state in new_states
  File "/home/ubuntu/.local/lib/python3.6/site-packages/mythril/laser/ethereum/svm.py", line 261, in <listcomp>
    if state.world_state.constraints.is_possible
  File "/home/ubuntu/.local/lib/python3.6/site-packages/mythril/laser/ethereum/state/constraints.py", line 32, in is_possible
    get_model(tuple(self[:]))
  File "/home/ubuntu/.local/lib/python3.6/site-packages/mythril/support/model.py", line 57, in get_model
    result = s.check()
  File "/home/ubuntu/.local/lib/python3.6/site-packages/mythril/laser/smt/solver/solver_statistics.py", line 19, in function_wrapper
    result = func(*args, **kwargs)
  File "/home/ubuntu/.local/lib/python3.6/site-packages/mythril/laser/smt/solver/solver.py", line 55, in check
    evaluate = self.raw.check(args)
  File "/home/ubuntu/.local/lib/python3.6/site-packages/z3/z3.py", line 7534, in check
    return CheckSatResult(Z3_optimize_check(self.ctx.ref(), self.optimize, num, _assumptions))
  File "/home/ubuntu/.local/lib/python3.6/site-packages/z3/z3core.py", line 4468, in Z3_optimize_check
    _elems.Check(a0)
  File "/home/ubuntu/.local/lib/python3.6/site-packages/z3/z3core.py", line 1420, in Check
    raise self.Exception(self.get_error_message(ctx, err))
z3.z3types.Z3Exception: b'push canceled'

mythril.mythril.mythril_analyzer [CRITICAL]: Exception occurred, aborting analysis. Please report this issue to the Mythril GitHub page.
Traceback (most recent call last):
  File "/home/ubuntu/.local/lib/python3.6/site-packages/mythril/mythril/mythril_analyzer.py", line 162, in fire_lasers
    custom_modules_directory=self.custom_modules_directory,
  File "/home/ubuntu/.local/lib/python3.6/site-packages/mythril/analysis/symbolic.py", line 166, in __init__
    world_state=world_state,
  File "/home/ubuntu/.local/lib/python3.6/site-packages/mythril/laser/ethereum/svm.py", line 175, in sym_exec
    self._execute_transactions(created_account.address)
  File "/home/ubuntu/.local/lib/python3.6/site-packages/mythril/laser/ethereum/svm.py", line 216, in _execute_transactions
    execute_message_call(self, address)
  File "/home/ubuntu/.local/lib/python3.6/site-packages/mythril/laser/ethereum/transaction/symbolic.py", line 108, in execute_message_call
    laser_evm.exec()
  File "/home/ubuntu/.local/lib/python3.6/site-packages/mythril/laser/ethereum/svm.py", line 253, in exec
    new_states, op_code = self.execute_state(global_state)
  File "/home/ubuntu/.local/lib/python3.6/site-packages/mythril/laser/ethereum/svm.py", line 346, in execute_state
    ).evaluate(global_state)
  File "/home/ubuntu/.local/lib/python3.6/site-packages/mythril/laser/ethereum/instructions.py", line 260, in evaluate
    result = instruction_mutator(global_state)
  File "/home/ubuntu/.local/lib/python3.6/site-packages/mythril/laser/ethereum/instructions.py", line 192, in wrapper
    new_global_states = self.call_on_state_copy(func, func_obj, global_state)
  File "/home/ubuntu/.local/lib/python3.6/site-packages/mythril/laser/ethereum/instructions.py", line 127, in call_on_state_copy
    return func(func_obj, global_state_copy)
  File "/home/ubuntu/.local/lib/python3.6/site-packages/mythril/laser/ethereum/instructions.py", line 919, in balance_
    address.value, self.dynamic_loader
  File "/home/ubuntu/.local/lib/python3.6/site-packages/mythril/laser/ethereum/state/world_state.py", line 125, in accounts_exist_or_load
    code=dynamic_loader.dynld(addr),
  File "/home/ubuntu/.local/lib/python3.6/site-packages/mythril/support/loader.py", line 67, in dynld
    raise ValueError("Cannot load from the chain when eth is None")
ValueError: Cannot load from the chain when eth is None


---------------------------------------------
For contract 0x7b6c0726c8d2da330bf5c65c6889ee268cd19466.sol
Tool Runtime = 3776.4652976020006 seconds
#############################################