mythril.mythril.mythril_analyzer [CRITICAL]: Exception occurred, aborting analysis. Please report this issue to the Mythril GitHub page.
Traceback (most recent call last):
  File "/home/ubuntu/.local/lib/python3.6/site-packages/mythril/mythril/mythril_analyzer.py", line 162, in fire_lasers
    custom_modules_directory=self.custom_modules_directory,
  File "/home/ubuntu/.local/lib/python3.6/site-packages/mythril/analysis/symbolic.py", line 166, in __init__
    world_state=world_state,
  File "/home/ubuntu/.local/lib/python3.6/site-packages/mythril/laser/ethereum/svm.py", line 175, in sym_exec
    self._execute_transactions(created_account.address)
  File "/home/ubuntu/.local/lib/python3.6/site-packages/mythril/laser/ethereum/svm.py", line 216, in _execute_transactions
    execute_message_call(self, address)
  File "/home/ubuntu/.local/lib/python3.6/site-packages/mythril/laser/ethereum/transaction/symbolic.py", line 108, in execute_message_call
    laser_evm.exec()
  File "/home/ubuntu/.local/lib/python3.6/site-packages/mythril/laser/ethereum/svm.py", line 260, in exec
    for state in new_states
  File "/home/ubuntu/.local/lib/python3.6/site-packages/mythril/laser/ethereum/svm.py", line 261, in <listcomp>
    if state.world_state.constraints.is_possible
  File "/home/ubuntu/.local/lib/python3.6/site-packages/mythril/laser/ethereum/state/constraints.py", line 32, in is_possible
    get_model(tuple(self[:]))
  File "/home/ubuntu/.local/lib/python3.6/site-packages/mythril/support/model.py", line 57, in get_model
    result = s.check()
  File "/home/ubuntu/.local/lib/python3.6/site-packages/mythril/laser/smt/solver/solver_statistics.py", line 19, in function_wrapper
    result = func(*args, **kwargs)
  File "/home/ubuntu/.local/lib/python3.6/site-packages/mythril/laser/smt/solver/solver.py", line 55, in check
    evaluate = self.raw.check(args)
  File "/home/ubuntu/.local/lib/python3.6/site-packages/z3/z3.py", line 7534, in check
    return CheckSatResult(Z3_optimize_check(self.ctx.ref(), self.optimize, num, _assumptions))
  File "/home/ubuntu/.local/lib/python3.6/site-packages/z3/z3core.py", line 4468, in Z3_optimize_check
    _elems.Check(a0)
  File "/home/ubuntu/.local/lib/python3.6/site-packages/z3/z3core.py", line 1420, in Check
    raise self.Exception(self.get_error_message(ctx, err))
z3.z3types.Z3Exception: b'push canceled'

mythril.interfaces.cli [ERROR]: Traceback (most recent call last):
  File "/home/ubuntu/.local/lib/python3.6/site-packages/mythril/interfaces/cli.py", line 845, in parse_args_and_execute
    disassembler=disassembler, address=address, parser=parser, args=args
  File "/home/ubuntu/.local/lib/python3.6/site-packages/mythril/interfaces/cli.py", line 757, in execute_command
    transaction_count=args.transaction_count,
  File "/home/ubuntu/.local/lib/python3.6/site-packages/mythril/mythril/mythril_analyzer.py", line 180, in fire_lasers
    issue.add_code_info(contract)
  File "/home/ubuntu/.local/lib/python3.6/site-packages/mythril/analysis/report.py", line 145, in add_code_info
    self.address, constructor=(self.function == "constructor")
  File "/home/ubuntu/.local/lib/python3.6/site-packages/mythril/solidity/soliditycontract.py", line 195, in get_source_info
    solidity_file = self.solc_indices[mappings[index].solidity_file_idx]
KeyError: -1
 

---------------------------------------------
For contract 0x9d7242f7f2514e0cc5e691dc6d3c789ea184bf8c.sol
Tool Runtime = 5095.568604300992 seconds
#############################################