mythril.mythril [CRITICAL]: Exception occurred, aborting analysis. Please report this issue to the Mythril GitHub page.
Traceback (most recent call last):
  File "/home/ubuntu/Mpro/M-Pro/mythril/mythril.py", line 629, in slither_mythril
    heuristic=priority
  File "/home/ubuntu/Mpro/M-Pro/mythril/analysis/symbolic.py", line 103, in __init__
    creation_code=contract.creation_code, contract_name=contract.name, heuristic=heuristic, disassembly = contract.disassembly
  File "/home/ubuntu/Mpro/M-Pro/mythril/laser/ethereum/svm.py", line 162, in sym_exec
    self._execute_transactions(created_account.address, heuristic, disassembly)
  File "/home/ubuntu/Mpro/M-Pro/mythril/laser/ethereum/svm.py", line 205, in _execute_transactions
    heuristic_message_call(self, address, heuristic, self.transaction_count, disassembly)
  File "/home/ubuntu/Mpro/M-Pro/mythril/laser/ethereum/transaction/symbolic.py", line 30, in heuristic_message_call
    execute_message_call(laser_evm, callee_address, disassembly)
  File "/home/ubuntu/Mpro/M-Pro/mythril/laser/ethereum/transaction/symbolic.py", line 143, in execute_message_call
    laser_evm.exec(disassembly)
  File "/home/ubuntu/Mpro/M-Pro/mythril/laser/ethereum/svm.py", line 254, in exec
    new_states, op_code = self.execute_state(global_state, disassembly, priority=priotity)
  File "/home/ubuntu/Mpro/M-Pro/mythril/laser/ethereum/svm.py", line 299, in execute_state
    self._execute_pre_hook(op_code, global_state, self.time, len(global_state.world_state.transaction_sequence) - 1)
  File "/home/ubuntu/Mpro/M-Pro/mythril/laser/ethereum/svm.py", line 573, in _execute_pre_hook
    hook(global_state, start_time, transaction_lenth)
  File "/home/ubuntu/Mpro/M-Pro/mythril/analysis/modules/integer.py", line 80, in execute
    self._handle_mul(state)
  File "/home/ubuntu/Mpro/M-Pro/mythril/analysis/modules/integer.py", line 114, in _handle_mul
    model = self._try_constraints(state.node.constraints, [c])
  File "/home/ubuntu/Mpro/M-Pro/mythril/analysis/modules/integer.py", line 287, in _try_constraints
    return solver.get_model(constraints + new_constraints)
  File "/home/ubuntu/Mpro/M-Pro/mythril/analysis/solver.py", line 42, in get_model
    result = s.check()
  File "/home/ubuntu/Mpro/M-Pro/mythril/laser/smt/solver.py", line 51, in check
    return self.raw.check()
  File "/home/ubuntu/.local/lib/python3.6/site-packages/z3/z3.py", line 7368, in check
    return CheckSatResult(Z3_optimize_check(self.ctx.ref(), self.optimize, num, _assumptions))
  File "/home/ubuntu/.local/lib/python3.6/site-packages/z3/z3core.py", line 4053, in Z3_optimize_check
    _elems.Check(a0)
  File "/home/ubuntu/.local/lib/python3.6/site-packages/z3/z3core.py", line 1348, in Check
    raise self.Exception(self.get_error_message(ctx, err))
z3.z3types.Z3Exception: b'out of memory'
 
Traceback (most recent call last):
  File "myth", line 9, in <module>
    mythril.interfaces.cli.main()
  File "/home/ubuntu/Mpro/M-Pro/mythril/interfaces/cli.py", line 440, in main
    file=args.solidity_file)
  File "/home/ubuntu/Mpro/M-Pro/mythril/mythril.py", line 647, in slither_mythril
    global_total_states += sym.laser.total_states
UnboundLocalError: local variable 'sym' referenced before assignment

---------------------------------------------
For contract 0xe5ea161e0a297daadbf330abcdf15fff0d62b4b4.sol
Tool Runtime = 4270.059783247998 seconds
#############################################